<?xml version='1.0' encoding='utf-8'?>
<robot name="doosan_allegro">
  <link name="arm_base" />
  <joint name="arm_fixed" type="fixed">
    <parent link="arm_base" />
    <child link="arm_base_link" />
  </joint>
  <link name="arm_base_link">
    <inertial>
      <mass value="3.722" />
      <origin xyz="-1.2e-05 -6e-05 0.050723" />
      <inertia ixx="0.011" ixy="-7.19e-06" ixz="-1.94e-06" iyy="0.011" iyz="4.9e-06" izz="0.014" />
    </inertial>
    <visual>
      <origin rpy="0 0 0" xyz="0 0 0" />
      <geometry>
        <mesh filename="doosan_a0509/meshes/A0509_0_0.dae" scale="0.001 0.001 0.001" />
      </geometry>
    </visual>
  </link>
  <joint name="arm_joint_1" type="revolute">
    <parent link="arm_base_link" />
    <child link="arm_link_1" />
    <origin rpy="0 0 0" xyz="0 0 0.1560" />
    <axis xyz="0 0 1" />
    <limit effort="30" lower="-2.617" upper="2.617" velocity="1.571" />
  </joint>
  <link name="arm_link_1">
    <inertial>
      <mass value="7.446" />
      <origin xyz="7e-05 0.044281 0.143327" />
      <inertia ixx="0.039" ixy="2.1e-05" ixz="-3.61e-05" iyy="0.023" iyz="-0.003" izz="0.039" />
    </inertial>
    <visual>
      <origin rpy="0 0 0" xyz="0 0 0" />
      <geometry>
        <mesh filename="doosan_a0509/meshes/A0509_1_0.dae" scale="0.001 0.001 0.001" />
      </geometry>
    </visual>
    <visual>
      <origin rpy="0 0 0" xyz="0 0 0" />
      <geometry>
        <mesh filename="doosan_a0509/meshes/A0509_1_1.dae" scale="0.001 0.001 0.001" />
      </geometry>
    </visual>
    <visual>
      <origin rpy="0 0 0" xyz="0 0 0" />
      <geometry>
        <mesh filename="doosan_a0509/meshes/A0509_1_2.dae" scale="0.001 0.001 0.001" />
      </geometry>
    </visual>
  </link>
  <joint name="arm_joint_2" type="revolute">
    <parent link="arm_link_1" />
    <child link="arm_link_2" />
    <origin rpy="0 -1.571 -1.571" xyz="0 0 0" />
    <axis xyz="0 0 1" />
    <limit effort="30" lower="-2.617" upper="2.617" velocity="1.571" />
  </joint>
  <link name="arm_link_2">
    <inertial>
      <mass value="10.569" />
      <origin xyz="-1.6e-05 0.189372 0.418558" />
      <inertia ixx="0.820" ixy="1.19e-05" ixz="-0.000263" iyy="0.82" iyz="-0.008" izz="0.031" />
    </inertial>
    <visual>
      <origin rpy="0 0 0" xyz="0 0 0" />
      <geometry>
        <mesh filename="doosan_a0509/meshes/A0509_2_0.dae" scale="0.001 0.001 0.001" />
      </geometry>
    </visual>
    <visual>
      <origin rpy="0 0 0" xyz="0 0 0" />
      <geometry>
        <mesh filename="doosan_a0509/meshes/A0509_2_1.dae" scale="0.001 0.001 0.001" />
      </geometry>
    </visual>
    <visual>
      <origin rpy="0 0 0" xyz="0 0 0" />
      <geometry>
        <mesh filename="doosan_a0509/meshes/A0509_2_2.dae" scale="0.001 0.001 0.001" />
      </geometry>
    </visual>
  </link>
  <joint name="arm_joint_3" type="revolute">
    <parent link="arm_link_2" />
    <child link="arm_link_3" />
    <origin rpy="0 0 1.571" xyz="0.409 0 0" />
    <axis xyz="0 0 1" />
    <limit effort="30" lower="-2.617" upper="2.617" velocity="1.571" />
  </joint>
  <link name="arm_link_3">
    <inertial>
      <mass value="3.614" />
      <origin xyz="6e-06 0.07917 0.781807" />
      <inertia ixx="0.012" ixy="-4.38e-06" ixz="-1.2e-06" iyy="0.008" iyz="0.002" izz="0.011" />
    </inertial>
    <visual>
      <origin rpy="0 0 0" xyz="0 0 0" />
      <geometry>
        <mesh filename="doosan_a0509/meshes/A0509_3_0.dae" scale="0.001 0.001 0.001" />
      </geometry>
    </visual>
    <visual>
      <origin rpy="0 0 0" xyz="0 0 0" />
      <geometry>
        <mesh filename="doosan_a0509/meshes/A0509_3_1.dae" scale="0.001 0.001 0.001" />
      </geometry>
    </visual>
  </link>
  <joint name="arm_joint_4" type="revolute">
    <parent link="arm_link_3" />
    <child link="arm_link_4" />
    <origin rpy="1.571 0 0" xyz="0 -0.367 0" />
    <axis xyz="0 0 1" />
    <limit effort="30" lower="-2.617" upper="2.617" velocity="1.571" />
  </joint>
  <link name="arm_link_4">
    <inertial>
      <mass value="3.785" />
      <origin xyz="-2.1e-05 0.12337 1.148" />
      <inertia ixx="0.177" ixy="-2.34e-06" ixz="-4.92e-06" iyy="0.161" iyz="-0.05" izz="0.022" />
    </inertial>
    <visual>
      <origin rpy="0 0 0" xyz="0 0 0" />
      <geometry>
        <mesh filename="doosan_a0509/meshes/A0509_4_0.dae" scale="0.001 0.001 0.001" />
      </geometry>
    </visual>
    <visual>
      <origin rpy="0 0 0" xyz="0 0 0" />
      <geometry>
        <mesh filename="doosan_a0509/meshes/A0509_4_1.dae" scale="0.001 0.001 0.001" />
      </geometry>
    </visual>
  </link>
  <joint name="arm_joint_5" type="revolute">
    <parent link="arm_link_4" />
    <child link="arm_link_5" />
    <origin rpy="-1.571 0 0" xyz="0 0 0" />
    <axis xyz="0 0 1" />
    <limit effort="30" lower="-2.617" upper="2.617" velocity="1.571" />
  </joint>
  <link name="arm_link_5">
    <inertial>
      <mass value="2.598" />
      <origin xyz="-1.7e-05 0.06662 1.33103" />
      <inertia ixx="0.007" ixy="-4.93e-06" ixz="-5.57e-06" iyy="0.004" iyz="-6.64e-05" izz="0.007" />
    </inertial>
    <visual>
      <origin rpy="0 0 0" xyz="0 0 0" />
      <geometry>
        <mesh filename="doosan_a0509/meshes/A0509_5_0.dae" scale="0.001 0.001 0.001" />
      </geometry>
    </visual>
    <visual>
      <origin rpy="0 0 0" xyz="0 0 0" />
      <geometry>
        <mesh filename="doosan_a0509/meshes/A0509_5_1.dae" scale="0.001 0.001 0.001" />
      </geometry>
    </visual>
  </link>
  <joint name="arm_joint_6" type="revolute">
    <parent link="arm_link_5" />
    <child link="arm_link_6" />
    <origin rpy="1.571 0 0" xyz="0 -0.124 0" />
    <axis xyz="0 0 1" />
    <limit effort="30" lower="-2.617" upper="2.617" velocity="1.571" />
  </joint>
  <link name="arm_link_6">
    <inertial>
      <mass value="1.128" />
      <origin xyz="-0.000174 0.034708 1.40022" />
      <inertia ixx="0.001" ixy="-2.79e-06" ixz="5.78e-06" iyy="0.001" iyz="-6.67e-06" izz="0.001" />
    </inertial>
    <visual>
      <origin rpy="0 0 0" xyz="0 0 0" />
      <geometry>
        <mesh filename="doosan_a0509/meshes/A0509_6_0.dae" scale="0.001 0.001 0.001" />
      </geometry>
    </visual>
  </link>
  <joint name="arm_to_hand" type="fixed">
    <parent link="arm_link_6" />
    <child link="hand_hand_root" />
    <origin rpy="0 0 0" xyz="0 0 0" />
  </joint>
  <link name="hand_hand_root">
    <visual>
      <geometry>
        <box size="0.001 0.001 0.001" />
      </geometry>
    </visual>
    <collision>
      <geometry>
        <box size="0.001 0.001 0.001" />
      </geometry>
    </collision>
    <inertial>
      <mass value="0.01" />
      <origin rpy="0 0 0" xyz="0 0 0" />
      <inertia ixx="1e-7" ixy="0" ixz="0" iyy="1e-7" iyz="0" izz="1e-7" />
    </inertial>
  </link>
  <joint name="hand_root_to_base" type="fixed">
    <parent link="hand_hand_root" />
    <child link="hand_palm_link" />
    <origin xyz="0 0 0.095" />
  </joint>
  <link name="hand_palm_link">
    <visual>
      <origin rpy="0 0 0" xyz="-0.009300 0 -0.0475" />
      <geometry>
        <box size="0.0408 0.1130 0.095" />
      </geometry>
      <material name="black">
        <color rgba="0.2 0.2 0.2 1" />
      </material>
    </visual>
    <collision>
      <origin rpy="0 0 0" xyz="-0.009300 0 -0.0475" />
      <geometry>
        <box size="0.0408 0.1130 0.095" />
      </geometry>
    </collision>
    <inertial>
      <origin rpy="0 0 0" xyz="0 0 0" />
      <mass value="0.4154" />
      <inertia ixx="0.00208916" ixy="-3.63457e-06" ixz="0.000223277" iyy="0.00182848" iyz="-1.75634e-05" izz="0.000482459" />
    </inertial>
  </link>
  <link name="hand_link_0">
    <visual>
      <origin rpy="0 0 0" xyz="0 0 0.0082" />
      <geometry>
        <box size="0.0196 0.0275 0.0164" />
      </geometry>
      <material name="dark_grey">
        <color rgba="0.35 0.35 0.35 1" />
      </material>
    </visual>
    <collision>
      <geometry>
        <box size="0.0196 0.0275 0.0164" />
      </geometry>
      <origin rpy="0 0 0" xyz="0 0 0.0082" />
    </collision>
    <inertial>
      <mass value="0.0119" />
      <origin rpy="0 0 0" xyz="0 0 0" />
      <inertia ixx="1.95377e-06" ixy="3.03372e-09" ixz="8.92323e-08" iyy="1.17908e-06" iyz="-3.7069e-08" izz="1.49673e-06" />
    </inertial>
  </link>
  <joint name="hand_joint_0" type="revolute">
    <axis xyz="0 0 1" />
    <limit effort="0.7" lower="-0.47" upper="0.47" velocity="7" />
    <parent link="hand_palm_link" />
    <child link="hand_link_0" />
    <origin rpy="-0.08726646255 0 0" xyz="0 0.0435 -0.001542" />
    <dynamics damping="1.5e-2" friction="10" />
  </joint>
  <transmission name="hand_joint_0_trans" type="transmission_interface/SimpleTransmission">
    <actuator name="hand_joint_0_motor" />
    <joint name="hand_joint_0" />
    <mechanicalReduction>1</mechanicalReduction>
    <motorTorqueConstant>1</motorTorqueConstant>
  </transmission>
  <link name="hand_link_1">
    <visual>
      <origin rpy="0 0 0" xyz="0 0 0.027" />
      <geometry>
        <box size="0.0196 0.0275 0.054" />
      </geometry>
      <material name="grey">
        <color rgba="0.5 0.5 0.5 1" />
      </material>
    </visual>
    <collision>
      <geometry>
        <box size="0.0196 0.0275 0.054" />
      </geometry>
      <origin rpy="0 0 0" xyz="0 0 0.027" />
    </collision>
    <inertial>
      <mass value="0.065" />
      <origin rpy="0 0 0" xyz="0 0 0" />
      <inertia ixx="7.19218e-05" ixy="0" ixz="0" iyy="7.4377e-05" iyz="7.32186e-07" izz="5.40622e-06" />
    </inertial>
  </link>
  <joint name="hand_joint_1" type="revolute">
    <limit effort="0.7" lower="-0.196" upper="1.61" velocity="7" />
    <axis xyz="0 1 0" />
    <parent link="hand_link_0" />
    <child link="hand_link_1" />
    <origin xyz="0 0 0.0164" />
    <dynamics damping="1.5e-2" friction="5" />
  </joint>
  <transmission name="hand_joint_1_trans" type="transmission_interface/SimpleTransmission">
    <actuator name="hand_joint_1_motor" />
    <joint name="hand_joint_1" />
    <mechanicalReduction>1</mechanicalReduction>
    <motorTorqueConstant>1</motorTorqueConstant>
  </transmission>
  <link name="hand_link_2">
    <visual>
      <origin rpy="0 0 0" xyz="0 0 0.0192" />
      <geometry>
        <box size="0.0196 0.0275 0.0384" />
      </geometry>
      <material name="grey" />
    </visual>
    <collision>
      <geometry>
        <box size="0.0196 0.0275 0.0384" />
      </geometry>
      <origin rpy="0 0 0" xyz="0 0 0.0192" />
    </collision>
    <inertial>
      <mass value="0.0355" />
      <origin rpy="0 0 0" xyz="0 0 0" />
      <inertia ixx="3.16925e-05" ixy="1.07094e-09" ixz="-4.91273e-09" iyy="3.10516e-05" iyz="3.87549e-08" izz="3.20319e-06" />
    </inertial>
  </link>
  <joint name="hand_joint_2" type="revolute">
    <axis xyz="0 1 0" />
    <limit effort="0.7" lower="-0.174" upper="1.709" velocity="7" />
    <parent link="hand_link_1" />
    <child link="hand_link_2" />
    <origin xyz="0 0 0.054" />
    <dynamics damping="1.5e-2" friction="10" />
  </joint>
  <transmission name="hand_joint_2_trans" type="transmission_interface/SimpleTransmission">
    <actuator name="hand_joint_2_motor" />
    <joint name="hand_joint_2" />
    <mechanicalReduction>1</mechanicalReduction>
    <motorTorqueConstant>1</motorTorqueConstant>
  </transmission>
  <link name="hand_link_3">
    <visual>
      <origin rpy="0 0 0" xyz="0 0 0.01335" />
      <geometry>
        <box size="0.0196 0.0275 0.0267" />
      </geometry>
      <material name="grey" />
    </visual>
    <collision>
      <geometry>
        <box size="0.0196 0.0275 0.0267" />
      </geometry>
      <origin rpy="0 0 0" xyz="0 0 0.01335" />
    </collision>
    <inertial>
      <mass value="0.0096" />
      <origin rpy="0 0 0" xyz="0 0 0" />
      <inertia ixx="2.13975e-06" ixy="1.59554e-09" ixz="-7.47528e-09" iyy="1.52036e-06" iyz="-9.89336e-09" izz="1.20271e-06" />
    </inertial>
  </link>
  <joint name="hand_joint_3" type="revolute">
    <axis xyz="0 1 0" />
    <limit effort="0.7" lower="-0.227" upper="1.618" velocity="7" />
    <parent link="hand_link_2" />
    <child link="hand_link_3" />
    <origin xyz="0 0 0.0384" />
    <dynamics damping="1.5e-2" friction="12" />
  </joint>
  <transmission name="hand_joint_3_trans" type="transmission_interface/SimpleTransmission">
    <actuator name="hand_joint_3_motor" />
    <joint name="hand_joint_3" />
    <mechanicalReduction>1</mechanicalReduction>
    <motorTorqueConstant>1</motorTorqueConstant>
  </transmission>
  <link name="hand_link_3_tip">
    <visual>
      <geometry>
        <sphere radius="0.012" />
      </geometry>
      <material name="tip">
        <color rgba="0.85 0.6 0.45 1" />
      </material>
    </visual>
    <collision>
      <geometry>
        <sphere radius="0.012" />
      </geometry>
    </collision>
    <inertial>
      <mass value="0.0168" />
      <origin rpy="0 0 0" xyz="0 0 0" />
      <inertia ixx="1.19599e-05" ixy="0" ixz="0" iyy="1.19598e-05" iyz="0" izz="1.10345e-06" />
    </inertial>
  </link>
  <joint name="hand_joint_3_tip" type="fixed">
    <parent link="hand_link_3" />
    <child link="hand_link_3_tip" />
    <origin rpy="0 0 0" xyz="0 0 0.0267" />
  </joint>
  <link name="hand_link_4">
    <visual>
      <geometry>
        <box size="0.0196 0.0275 0.0164" />
      </geometry>
      <material name="black" />
    </visual>
    <collision>
      <geometry>
        <box size="0.0196 0.0275 0.0164" />
      </geometry>
      <origin rpy="0 0 0" xyz="0 0 0.0082" />
    </collision>
    <inertial>
      <mass value="0.0119" />
      <origin rpy="0 0 0" xyz="0 0 0" />
      <inertia ixx="1.95377e-06" ixy="3.03372e-09" ixz="8.92323e-08" iyy="1.17908e-06" iyz="-3.7069e-08" izz="1.49673e-06" />
    </inertial>
  </link>
  <joint name="hand_joint_4" type="revolute">
    <axis xyz="0 0 1" />
    <limit effort="0.7" lower="-0.47" upper="0.47" velocity="7" />
    <parent link="hand_palm_link" />
    <child link="hand_link_4" />
    <origin rpy="0.0 0 0" xyz="0 0 0.0007" />
    <dynamics damping="1.5e-2" friction="10" />
  </joint>
  <transmission name="hand_joint_4_trans" type="transmission_interface/SimpleTransmission">
    <actuator name="hand_joint_4_motor" />
    <joint name="hand_joint_4" />
    <mechanicalReduction>1</mechanicalReduction>
    <motorTorqueConstant>1</motorTorqueConstant>
  </transmission>
  <link name="hand_link_5">
    <visual>
      <geometry>
        <box size="0.0196 0.0275 0.054" />
      </geometry>
      <material name="black" />
    </visual>
    <collision>
      <geometry>
        <box size="0.0196 0.0275 0.054" />
      </geometry>
      <origin rpy="0 0 0" xyz="0 0 0.027" />
    </collision>
    <inertial>
      <mass value="0.065" />
      <origin rpy="0 0 0" xyz="0 0 0" />
      <inertia ixx="7.19218e-05" ixy="0" ixz="0" iyy="7.4377e-05" iyz="7.32186e-07" izz="5.40622e-06" />
    </inertial>
  </link>
  <joint name="hand_joint_5" type="revolute">
    <limit effort="0.7" lower="-0.196" upper="1.61" velocity="7" />
    <axis xyz="0 1 0" />
    <parent link="hand_link_4" />
    <child link="hand_link_5" />
    <origin xyz="0 0 0.0164" />
    <dynamics damping="1.5e-2" friction="5" />
  </joint>
  <transmission name="hand_joint_5_trans" type="transmission_interface/SimpleTransmission">
    <actuator name="hand_joint_5_motor" />
    <joint name="hand_joint_5" />
    <mechanicalReduction>1</mechanicalReduction>
    <motorTorqueConstant>1</motorTorqueConstant>
  </transmission>
  <link name="hand_link_6">
    <visual>
      <geometry>
        <box size="0.0196 0.0275 0.0384" />
      </geometry>
      <material name="black" />
    </visual>
    <collision>
      <geometry>
        <box size="0.0196 0.0275 0.0384" />
      </geometry>
      <origin rpy="0 0 0" xyz="0 0 0.0192" />
    </collision>
    <inertial>
      <mass value="0.0355" />
      <origin rpy="0 0 0" xyz="0 0 0" />
      <inertia ixx="3.16925e-05" ixy="1.07094e-09" ixz="-4.91273e-09" iyy="3.10516e-05" iyz="3.87549e-08" izz="3.20319e-06" />
    </inertial>
  </link>
  <joint name="hand_joint_6" type="revolute">
    <axis xyz="0 1 0" />
    <limit effort="0.7" lower="-0.174" upper="1.709" velocity="7" />
    <parent link="hand_link_5" />
    <child link="hand_link_6" />
    <origin xyz="0 0 0.054" />
    <dynamics damping="1.5e-2" friction="10" />
  </joint>
  <transmission name="hand_joint_6_trans" type="transmission_interface/SimpleTransmission">
    <actuator name="hand_joint_6_motor" />
    <joint name="hand_joint_6" />
    <mechanicalReduction>1</mechanicalReduction>
    <motorTorqueConstant>1</motorTorqueConstant>
  </transmission>
  <link name="hand_link_7">
    <visual>
      <geometry>
        <box size="0.0196 0.0275 0.0267" />
      </geometry>
      <material name="black" />
    </visual>
    <collision>
      <geometry>
        <box size="0.0196 0.0275 0.0267" />
      </geometry>
      <origin rpy="0 0 0" xyz="0 0 0.01335" />
    </collision>
    <inertial>
      <mass value="0.0096" />
      <origin rpy="0 0 0" xyz="0 0 0" />
      <inertia ixx="2.13975e-06" ixy="1.59554e-09" ixz="-7.47528e-09" iyy="1.52036e-06" iyz="-9.89336e-09" izz="1.20271e-06" />
    </inertial>
  </link>
  <joint name="hand_joint_7" type="revolute">
    <axis xyz="0 1 0" />
    <limit effort="0.7" lower="-0.227" upper="1.618" velocity="7" />
    <parent link="hand_link_6" />
    <child link="hand_link_7" />
    <origin xyz="0 0 0.0384" />
    <dynamics damping="1.5e-2" friction="12" />
  </joint>
  <transmission name="hand_joint_7_trans" type="transmission_interface/SimpleTransmission">
    <actuator name="hand_joint_7_motor" />
    <joint name="hand_joint_7" />
    <mechanicalReduction>1</mechanicalReduction>
    <motorTorqueConstant>1</motorTorqueConstant>
  </transmission>
  <link name="hand_link_7_tip">
    <visual>
      <geometry>
        <sphere radius="0.012" />
      </geometry>
      <material name="white">
        <color rgba=".9 .9 .9 1" />
      </material>
    </visual>
    <collision>
      <geometry>
        <sphere radius="0.012" />
      </geometry>
    </collision>
    <inertial>
      <mass value="0.0168" />
      <origin rpy="0 0 0" xyz="0 0 0" />
      <inertia ixx="1.19599e-05" ixy="0" ixz="0" iyy="1.19598e-05" iyz="0" izz="1.10345e-06" />
    </inertial>
  </link>
  <joint name="hand_joint_7_tip" type="fixed">
    <parent link="hand_link_7" />
    <child link="hand_link_7_tip" />
    <origin rpy="0 0 0" xyz="0 0 0.0267" />
  </joint>
  <link name="hand_link_8">
    <visual>
      <geometry>
        <box size="0.0196 0.0275 0.0164" />
      </geometry>
      <material name="black" />
    </visual>
    <collision>
      <geometry>
        <box size="0.0196 0.0275 0.0164" />
      </geometry>
      <origin rpy="0 0 0" xyz="0 0 0.0082" />
    </collision>
    <inertial>
      <mass value="0.0119" />
      <origin rpy="0 0 0" xyz="0 0 0" />
      <inertia ixx="1.95377e-06" ixy="3.03372e-09" ixz="8.92323e-08" iyy="1.17908e-06" iyz="-3.7069e-08" izz="1.49673e-06" />
    </inertial>
  </link>
  <joint name="hand_joint_8" type="revolute">
    <axis xyz="0 0 1" />
    <limit effort="0.7" lower="-0.47" upper="0.47" velocity="7" />
    <parent link="hand_palm_link" />
    <child link="hand_link_8" />
    <origin rpy="0.08726646255 0 0" xyz="0 -0.0435 -0.001542" />
    <dynamics damping="1.5e-2" friction="10" />
  </joint>
  <transmission name="hand_joint_8_trans" type="transmission_interface/SimpleTransmission">
    <actuator name="hand_joint_8_motor" />
    <joint name="hand_joint_8" />
    <mechanicalReduction>1</mechanicalReduction>
    <motorTorqueConstant>1</motorTorqueConstant>
  </transmission>
  <link name="hand_link_9">
    <visual>
      <geometry>
        <box size="0.0196 0.0275 0.054" />
      </geometry>
      <material name="black" />
    </visual>
    <collision>
      <geometry>
        <box size="0.0196 0.0275 0.054" />
      </geometry>
      <origin rpy="0 0 0" xyz="0 0 0.027" />
    </collision>
    <inertial>
      <mass value="0.065" />
      <origin rpy="0 0 0" xyz="0 0 0" />
      <inertia ixx="7.19218e-05" ixy="0" ixz="0" iyy="7.4377e-05" iyz="7.32186e-07" izz="5.40622e-06" />
    </inertial>
  </link>
  <joint name="hand_joint_9" type="revolute">
    <limit effort="0.7" lower="-0.196" upper="1.61" velocity="7" />
    <axis xyz="0 1 0" />
    <parent link="hand_link_8" />
    <child link="hand_link_9" />
    <origin xyz="0 0 0.0164" />
    <dynamics damping="1.5e-2" friction="5" />
  </joint>
  <transmission name="hand_joint_9_trans" type="transmission_interface/SimpleTransmission">
    <actuator name="hand_joint_9_motor" />
    <joint name="hand_joint_9" />
    <mechanicalReduction>1</mechanicalReduction>
    <motorTorqueConstant>1</motorTorqueConstant>
  </transmission>
  <link name="hand_link_10">
    <visual>
      <geometry>
        <box size="0.0196 0.0275 0.0384" />
      </geometry>
      <material name="black" />
    </visual>
    <collision>
      <geometry>
        <box size="0.0196 0.0275 0.0384" />
      </geometry>
      <origin rpy="0 0 0" xyz="0 0 0.0192" />
    </collision>
    <inertial>
      <mass value="0.0355" />
      <origin rpy="0 0 0" xyz="0 0 0" />
      <inertia ixx="3.16925e-05" ixy="1.07094e-09" ixz="-4.91273e-09" iyy="3.10516e-05" iyz="3.87549e-08" izz="3.20319e-06" />
    </inertial>
  </link>
  <joint name="hand_joint_10" type="revolute">
    <axis xyz="0 1 0" />
    <limit effort="0.7" lower="-0.174" upper="1.709" velocity="7" />
    <parent link="hand_link_9" />
    <child link="hand_link_10" />
    <origin xyz="0 0 0.054" />
    <dynamics damping="1.5e-2" friction="10" />
  </joint>
  <transmission name="hand_joint_10_trans" type="transmission_interface/SimpleTransmission">
    <actuator name="hand_joint_10_motor" />
    <joint name="hand_joint_10" />
    <mechanicalReduction>1</mechanicalReduction>
    <motorTorqueConstant>1</motorTorqueConstant>
  </transmission>
  <link name="hand_link_11">
    <visual>
      <geometry>
        <box size="0.0196 0.0275 0.0267" />
      </geometry>
      <material name="black" />
    </visual>
    <collision>
      <geometry>
        <box size="0.0196 0.0275 0.0267" />
      </geometry>
      <origin rpy="0 0 0" xyz="0 0 0.01335" />
    </collision>
    <inertial>
      <mass value="0.0096" />
      <origin rpy="0 0 0" xyz="0 0 0" />
      <inertia ixx="2.13975e-06" ixy="1.59554e-09" ixz="-7.47528e-09" iyy="1.52036e-06" iyz="-9.89336e-09" izz="1.20271e-06" />
    </inertial>
  </link>
  <joint name="hand_joint_11" type="revolute">
    <axis xyz="0 1 0" />
    <limit effort="0.7" lower="-0.227" upper="1.618" velocity="7" />
    <parent link="hand_link_10" />
    <child link="hand_link_11" />
    <origin xyz="0 0 0.0384" />
    <dynamics damping="1.5e-2" friction="12" />
  </joint>
  <transmission name="hand_joint_11_trans" type="transmission_interface/SimpleTransmission">
    <actuator name="hand_joint_11_motor" />
    <joint name="hand_joint_11" />
    <mechanicalReduction>1</mechanicalReduction>
    <motorTorqueConstant>1</motorTorqueConstant>
  </transmission>
  <link name="hand_link_11_tip">
    <visual>
      <geometry>
        <sphere radius="0.012" />
      </geometry>
      <material name="white">
        <color rgba=".9 .9 .9 1" />
      </material>
    </visual>
    <collision>
      <geometry>
        <sphere radius="0.012" />
      </geometry>
    </collision>
    <inertial>
      <mass value="0.0168" />
      <origin rpy="0 0 0" xyz="0 0 0" />
      <inertia ixx="1.19599e-05" ixy="0" ixz="0" iyy="1.19598e-05" iyz="0" izz="1.10345e-06" />
    </inertial>
  </link>
  <joint name="hand_joint_11_tip" type="fixed">
    <parent link="hand_link_11" />
    <child link="hand_link_11_tip" />
    <origin rpy="0 0 0" xyz="0 0 0.0267" />
  </joint>
  <link name="hand_link_12">
    <visual>
      <origin rpy="0 0 0" xyz="-0.0179 0.009 0.0145" />
      <geometry>
        <box size="0.0358 0.034 0.0455" />
      </geometry>
      <material name="black">
        <color rgba=".2 .2 .2 1" />
      </material>
    </visual>
    <collision>
      <geometry>
        <box size="0.0358 0.034 0.0455" />
      </geometry>
      <origin rpy="0 0 0" xyz="-0.0179 0.009 0.0145" />
    </collision>
    <inertial>
      <mass value="0.0176" />
      <origin rpy="0 0 0" xyz="0 0 0" />
      <inertia ixx="8.13883e-06" ixy="2.55226e-06" ixz="3.89933e-06" iyy="1.31421e-05" iyz="-1.46267e-06" izz="1.00171e-05" />
    </inertial>
  </link>
  <joint name="hand_joint_12" type="revolute">
    <axis xyz="-1 0 0" />
    <limit effort="0.7" lower="0.263" upper="1.396" velocity="7" />
    <parent link="hand_palm_link" />
    <child link="hand_link_12" />
    <origin rpy="0 -1.65806278845 -1.5707963259" xyz="-0.0182 0.019333 -0.045987" />
    <dynamics damping="1.5e-2" friction="10" />
  </joint>
  <transmission name="hand_joint_12_trans" type="transmission_interface/SimpleTransmission">
    <actuator name="hand_joint_12_motor" />
    <joint name="hand_joint_12" />
    <mechanicalReduction>1</mechanicalReduction>
    <motorTorqueConstant>1</motorTorqueConstant>
  </transmission>
  <link name="hand_link_13">
    <visual>
      <origin rpy="0 0 0" xyz="0 0 0.00885" />
      <geometry>
        <box size="0.0196 0.0275 0.0177" />
      </geometry>
      <material name="black">
        <color rgba=".2 .2 .2 1" />
      </material>
    </visual>
    <collision>
      <geometry>
        <box size="0.0196 0.0275 0.0177" />
      </geometry>
      <origin rpy="0 0 0" xyz="0 0 0.00885" />
    </collision>
    <inertial>
      <mass value="0.0119" />
      <origin rpy="0 0 0" xyz="0 0 0" />
      <inertia ixx="1.9263e-06" ixy="3.05433e-09" ixz="8.86582e-08" iyy="1.15276e-06" iyz="-3.64521e-08" izz="1.4957e-06" />
    </inertial>
  </link>
  <joint name="hand_joint_13" type="revolute">
    <axis xyz="0 0 1" />
    <limit effort="0.7" lower="-0.105" upper="1.163" velocity="7" />
    <parent link="hand_link_12" />
    <child link="hand_link_13" />
    <origin xyz="-0.027 0.005 0.0399" />
    <dynamics damping="1.5e-2" friction="5" />
  </joint>
  <transmission name="hand_joint_13_trans" type="transmission_interface/SimpleTransmission">
    <actuator name="hand_joint_13_motor" />
    <joint name="hand_joint_13" />
    <mechanicalReduction>1</mechanicalReduction>
    <motorTorqueConstant>1</motorTorqueConstant>
  </transmission>
  <link name="hand_link_14">
    <visual>
      <origin rpy="0 0 0" xyz="0 0 0.0257" />
      <geometry>
        <box size="0.0196 0.0275 0.0514" />
      </geometry>
      <material name="black">
      </material>
    </visual>
    <collision>
      <geometry>
        <box size="0.0196 0.0275 0.0514" />
      </geometry>
      <origin rpy="0 0 0" xyz="0 0 0.0257" />
    </collision>
    <inertial>
      <mass value="0.038" />
      <origin rpy="0 0 0" xyz="0 0 0" />
      <inertia ixx="3.67044e-05" ixy="1.02277e-09" ixz="1.4854e-07" iyy="3.54042e-05" iyz="-3.67203e-08" izz="3.63275e-06" />
    </inertial>
  </link>
  <joint name="hand_joint_14" type="revolute">
    <axis xyz="0 1 0" />
    <limit effort="0.7" lower="-0.189" upper="1.644" velocity="7" />
    <parent link="hand_link_13" />
    <child link="hand_link_14" />
    <origin xyz="0 0 0.0177" />
    <dynamics damping="1.5e-2" friction="10" />
  </joint>
  <transmission name="hand_joint_14_trans" type="transmission_interface/SimpleTransmission">
    <actuator name="hand_joint_14_motor" />
    <joint name="hand_joint_14" />
    <mechanicalReduction>1</mechanicalReduction>
    <motorTorqueConstant>1</motorTorqueConstant>
  </transmission>
  <link name="hand_link_15">
    <visual>
      <origin rpy="0 0 0" xyz="0 0 0.02115" />
      <geometry>
        <box size="0.0196 0.0275 0.0423" />
      </geometry>
      <material name="black">
      </material>
    </visual>
    <collision>
      <geometry>
        <box size="0.0196 0.0275 0.0423" />
      </geometry>
      <origin rpy="0 0 0" xyz="0 0 0.02115" />
    </collision>
    <inertial>
      <mass value="0.0388" />
      <origin rpy="0 0 0" xyz="0 0 0" />
      <inertia ixx="4.30919e-05" ixy="0" ixz="0" iyy="3.85425e-05" iyz="-3.0146e-08" izz="1.72974e-05" />
    </inertial>
  </link>
  <joint name="hand_joint_15" type="revolute">
    <axis xyz="0 1 0" />
    <limit effort="0.7" lower="-0.162" upper="1.719" velocity="7" />
    <parent link="hand_link_14" />
    <child link="hand_link_15" />
    <origin xyz="0 0 0.0514" />
    <dynamics damping="1.5e-2" friction="12" />
  </joint>
  <transmission name="hand_joint_15_trans" type="transmission_interface/SimpleTransmission">
    <actuator name="hand_joint_15_motor" />
    <joint name="hand_joint_15" />
    <mechanicalReduction>1</mechanicalReduction>
    <motorTorqueConstant>1</motorTorqueConstant>
  </transmission>
  <link name="hand_link_15_tip">
    <visual>
      <geometry>
        <sphere radius="0.012" />
      </geometry>
      <material name="tip">
        <color rgba="0.85 0.6 0.45 1" />
      </material>
    </visual>
    <collision>
      <geometry>
        <sphere radius="0.012" />
      </geometry>
      <origin rpy="0 0 0" xyz="0 0 0" />
    </collision>
    <inertial>
      <mass value="0.0168" />
      <origin rpy="0 0 0" xyz="0 0 0" />
      <inertia ixx="1.19599e-05" ixy="0" ixz="0" iyy="1.19598e-05" iyz="0" izz="1.10345e-06" />
    </inertial>
  </link>
  <joint name="hand_joint_15_tip" type="fixed">
    <parent link="hand_link_15" />
    <child link="hand_link_15_tip" />
    <origin rpy="0 0 0" xyz="0 0 0.0423" />
  </joint>
</robot>